Hello world!
Traceback (most recent call last):
  File "main.py", line 7, in <module>
    import Register
  File "/var/www/azDNA/azDNA/Register.py", line 27
    verifycode = binascii.b2a_hex(os.urandom(15)).decode("utf-8")
                                                                ^
IndentationError: unindent does not match any outer indentation level
 * Serving Flask app "main" (lazy loading)
 * Environment: production
   WARNING: This is a development server. Do not use it in a production deployment.
   Use a production WSGI server instead.
 * Debug mode: off
 * Running on http://0.0.0.0:9000/ (Press CTRL+C to quit)
172.31.35.238 - - [23/Apr/2020 22:40:19] "[32mGET / HTTP/1.1[0m" 302 -
172.31.35.238 - - [23/Apr/2020 22:40:19] "[37mGET /login HTTP/1.1[0m" 200 -
172.31.35.238 - - [23/Apr/2020 22:40:19] "[37mGET /all_jobs HTTP/1.1[0m" 200 -
172.31.35.238 - - [23/Apr/2020 22:40:20] "[37mGET /all_jobs HTTP/1.1[0m" 200 -
172.31.35.238 - - [23/Apr/2020 22:40:33] "[32mPOST /register HTTP/1.1[0m" 302 -
172.31.35.238 - - [23/Apr/2020 22:40:33] "[37mGET /login HTTP/1.1[0m" 200 -
172.31.35.238 - - [23/Apr/2020 22:40:33] "[37mGET /all_jobs HTTP/1.1[0m" 200 -
172.31.35.238 - - [23/Apr/2020 22:40:35] "[37mGET /register HTTP/1.1[0m" 200 -
172.31.35.238 - - [23/Apr/2020 22:40:35] "[37mGET /all_jobs HTTP/1.1[0m" 200 -
[2020-04-23 22:41:13,897] ERROR in app: Exception on /register [POST]
Traceback (most recent call last):
  File "/home/capstonegroup/.local/lib/python3.6/site-packages/flask/app.py", line 2446, in wsgi_app
    response = self.full_dispatch_request()
  File "/home/capstonegroup/.local/lib/python3.6/site-packages/flask/app.py", line 1951, in full_dispatch_request
    rv = self.handle_user_exception(e)
  File "/home/capstonegroup/.local/lib/python3.6/site-packages/flask/app.py", line 1820, in handle_user_exception
    reraise(exc_type, exc_value, tb)
  File "/home/capstonegroup/.local/lib/python3.6/site-packages/flask/_compat.py", line 39, in reraise
    raise value
  File "/home/capstonegroup/.local/lib/python3.6/site-packages/flask/app.py", line 1949, in full_dispatch_request
    rv = self.dispatch_request()
  File "/home/capstonegroup/.local/lib/python3.6/site-packages/flask/app.py", line 1935, in dispatch_request
    return self.view_functions[rule.endpoint](**req.view_args)
  File "main.py", line 156, in register
    if(user_id > -1):
TypeError: '>' not supported between instances of 'NoneType' and 'int'
172.31.35.238 - - [23/Apr/2020 22:41:13] "[35m[1mPOST /register HTTP/1.1[0m" 500 -
172.31.35.238 - - [23/Apr/2020 22:41:50] "[37mGET /register HTTP/1.1[0m" 200 -
172.31.35.238 - - [23/Apr/2020 22:41:50] "[37mGET /all_jobs HTTP/1.1[0m" 200 -
[2020-04-23 22:41:57,708] ERROR in app: Exception on /register [POST]
Traceback (most recent call last):
  File "/home/capstonegroup/.local/lib/python3.6/site-packages/flask/app.py", line 2446, in wsgi_app
    response = self.full_dispatch_request()
  File "/home/capstonegroup/.local/lib/python3.6/site-packages/flask/app.py", line 1951, in full_dispatch_request
    rv = self.handle_user_exception(e)
  File "/home/capstonegroup/.local/lib/python3.6/site-packages/flask/app.py", line 1820, in handle_user_exception
    reraise(exc_type, exc_value, tb)
  File "/home/capstonegroup/.local/lib/python3.6/site-packages/flask/_compat.py", line 39, in reraise
    raise value
  File "/home/capstonegroup/.local/lib/python3.6/site-packages/flask/app.py", line 1949, in full_dispatch_request
    rv = self.dispatch_request()
  File "/home/capstonegroup/.local/lib/python3.6/site-packages/flask/app.py", line 1935, in dispatch_request
    return self.view_functions[rule.endpoint](**req.view_args)
  File "main.py", line 154, in register
    user_id = Register.registerUser(username, password, firstName, lastName, institution)
  File "/var/www/azDNA/azDNA/Register.py", line 26, in registerUser
    cursor.execute(add_user_query, user_data)
  File "/home/capstonegroup/.local/lib/python3.6/site-packages/mysql/connector/cursor.py", line 551, in execute
    self._handle_result(self._connection.cmd_query(stmt))
  File "/home/capstonegroup/.local/lib/python3.6/site-packages/mysql/connector/connection.py", line 490, in cmd_query
    result = self._handle_result(self._send_cmd(ServerCmd.QUERY, query))
  File "/home/capstonegroup/.local/lib/python3.6/site-packages/mysql/connector/connection.py", line 395, in _handle_result
    raise errors.get_exception(packet)
mysql.connector.errors.IntegrityError: 1062 (23000): Duplicate entry 'bob@bob.edu' for key 'username'
172.31.35.238 - - [23/Apr/2020 22:41:57] "[35m[1mPOST /register HTTP/1.1[0m" 500 -
[2020-04-23 22:43:09,850] ERROR in app: Exception on /register [POST]
Traceback (most recent call last):
  File "/home/capstonegroup/.local/lib/python3.6/site-packages/flask/app.py", line 2446, in wsgi_app
    response = self.full_dispatch_request()
  File "/home/capstonegroup/.local/lib/python3.6/site-packages/flask/app.py", line 1951, in full_dispatch_request
    rv = self.handle_user_exception(e)
  File "/home/capstonegroup/.local/lib/python3.6/site-packages/flask/app.py", line 1820, in handle_user_exception
    reraise(exc_type, exc_value, tb)
  File "/home/capstonegroup/.local/lib/python3.6/site-packages/flask/_compat.py", line 39, in reraise
    raise value
  File "/home/capstonegroup/.local/lib/python3.6/site-packages/flask/app.py", line 1949, in full_dispatch_request
    rv = self.dispatch_request()
  File "/home/capstonegroup/.local/lib/python3.6/site-packages/flask/app.py", line 1935, in dispatch_request
    return self.view_functions[rule.endpoint](**req.view_args)
  File "main.py", line 154, in register
    user_id = Register.registerUser(username, password, firstName, lastName, institution)
  File "/var/www/azDNA/azDNA/Register.py", line 26, in registerUser
    cursor.execute(add_user_query, user_data)
  File "/home/capstonegroup/.local/lib/python3.6/site-packages/mysql/connector/cursor.py", line 551, in execute
    self._handle_result(self._connection.cmd_query(stmt))
  File "/home/capstonegroup/.local/lib/python3.6/site-packages/mysql/connector/connection.py", line 490, in cmd_query
    result = self._handle_result(self._send_cmd(ServerCmd.QUERY, query))
  File "/home/capstonegroup/.local/lib/python3.6/site-packages/mysql/connector/connection.py", line 395, in _handle_result
    raise errors.get_exception(packet)
mysql.connector.errors.DatabaseError: 1205 (HY000): Lock wait timeout exceeded; try restarting transaction
172.31.35.238 - - [23/Apr/2020 22:43:09] "[35m[1mPOST /register HTTP/1.1[0m" 500 -
 * Serving Flask app "main" (lazy loading)
 * Environment: production
   WARNING: This is a development server. Do not use it in a production deployment.
   Use a production WSGI server instead.
 * Debug mode: off
Traceback (most recent call last):
  File "main.py", line 395, in <module>
    app.run(host="0.0.0.0", port=9000)
  File "/home/capstonegroup/.local/lib/python3.6/site-packages/flask/app.py", line 990, in run
    run_simple(host, port, self, **options)
  File "/home/capstonegroup/.local/lib/python3.6/site-packages/werkzeug/serving.py", line 1052, in run_simple
    inner()
  File "/home/capstonegroup/.local/lib/python3.6/site-packages/werkzeug/serving.py", line 1005, in inner
    fd=fd,
  File "/home/capstonegroup/.local/lib/python3.6/site-packages/werkzeug/serving.py", line 848, in make_server
    host, port, app, request_handler, passthrough_errors, ssl_context, fd=fd
  File "/home/capstonegroup/.local/lib/python3.6/site-packages/werkzeug/serving.py", line 740, in __init__
    HTTPServer.__init__(self, server_address, handler)
  File "/usr/lib/python3.6/socketserver.py", line 456, in __init__
    self.server_bind()
  File "/usr/lib/python3.6/http/server.py", line 136, in server_bind
    socketserver.TCPServer.server_bind(self)
  File "/usr/lib/python3.6/socketserver.py", line 470, in server_bind
    self.socket.bind(self.server_address)
OSError: [Errno 98] Address already in use
172.31.35.238 - - [23/Apr/2020 22:43:43] "[37mGET /all_jobs HTTP/1.1[0m" 200 -
[2020-04-23 22:44:45,785] ERROR in app: Exception on /register [POST]
Traceback (most recent call last):
  File "/home/capstonegroup/.local/lib/python3.6/site-packages/flask/app.py", line 2446, in wsgi_app
    response = self.full_dispatch_request()
  File "/home/capstonegroup/.local/lib/python3.6/site-packages/flask/app.py", line 1951, in full_dispatch_request
    rv = self.handle_user_exception(e)
  File "/home/capstonegroup/.local/lib/python3.6/site-packages/flask/app.py", line 1820, in handle_user_exception
    reraise(exc_type, exc_value, tb)
  File "/home/capstonegroup/.local/lib/python3.6/site-packages/flask/_compat.py", line 39, in reraise
    raise value
  File "/home/capstonegroup/.local/lib/python3.6/site-packages/flask/app.py", line 1949, in full_dispatch_request
    rv = self.dispatch_request()
  File "/home/capstonegroup/.local/lib/python3.6/site-packages/flask/app.py", line 1935, in dispatch_request
    return self.view_functions[rule.endpoint](**req.view_args)
  File "main.py", line 154, in register
    user_id = Register.registerUser(username, password, firstName, lastName, institution)
  File "/var/www/azDNA/azDNA/Register.py", line 26, in registerUser
    cursor.execute(add_user_query, user_data)
  File "/home/capstonegroup/.local/lib/python3.6/site-packages/mysql/connector/cursor.py", line 551, in execute
    self._handle_result(self._connection.cmd_query(stmt))
  File "/home/capstonegroup/.local/lib/python3.6/site-packages/mysql/connector/connection.py", line 490, in cmd_query
    result = self._handle_result(self._send_cmd(ServerCmd.QUERY, query))
  File "/home/capstonegroup/.local/lib/python3.6/site-packages/mysql/connector/connection.py", line 395, in _handle_result
    raise errors.get_exception(packet)
mysql.connector.errors.DatabaseError: 1205 (HY000): Lock wait timeout exceeded; try restarting transaction
172.31.35.238 - - [23/Apr/2020 22:44:45] "[35m[1mPOST /register HTTP/1.1[0m" 500 -
 * Serving Flask app "main" (lazy loading)
 * Environment: production
   WARNING: This is a development server. Do not use it in a production deployment.
   Use a production WSGI server instead.
 * Debug mode: off
Traceback (most recent call last):
  File "main.py", line 395, in <module>
    app.run(host="0.0.0.0", port=9000)
  File "/home/capstonegroup/.local/lib/python3.6/site-packages/flask/app.py", line 990, in run
    run_simple(host, port, self, **options)
  File "/home/capstonegroup/.local/lib/python3.6/site-packages/werkzeug/serving.py", line 1052, in run_simple
    inner()
  File "/home/capstonegroup/.local/lib/python3.6/site-packages/werkzeug/serving.py", line 1005, in inner
    fd=fd,
  File "/home/capstonegroup/.local/lib/python3.6/site-packages/werkzeug/serving.py", line 848, in make_server
    host, port, app, request_handler, passthrough_errors, ssl_context, fd=fd
  File "/home/capstonegroup/.local/lib/python3.6/site-packages/werkzeug/serving.py", line 740, in __init__
    HTTPServer.__init__(self, server_address, handler)
  File "/usr/lib/python3.6/socketserver.py", line 456, in __init__
    self.server_bind()
  File "/usr/lib/python3.6/http/server.py", line 136, in server_bind
    socketserver.TCPServer.server_bind(self)
  File "/usr/lib/python3.6/socketserver.py", line 470, in server_bind
    self.socket.bind(self.server_address)
OSError: [Errno 98] Address already in use
 * Serving Flask app "main" (lazy loading)
 * Environment: production
   WARNING: This is a development server. Do not use it in a production deployment.
   Use a production WSGI server instead.
 * Debug mode: off
 * Running on http://0.0.0.0:9000/ (Press CTRL+C to quit)
172.31.35.238 - - [23/Apr/2020 22:46:33] "[32mGET / HTTP/1.1[0m" 302 -
172.31.35.238 - - [23/Apr/2020 22:46:33] "[37mGET /login HTTP/1.1[0m" 200 -
172.31.35.238 - - [23/Apr/2020 22:46:33] "[37mGET /all_jobs HTTP/1.1[0m" 200 -
172.31.35.238 - - [23/Apr/2020 22:46:35] "[37mGET /all_jobs HTTP/1.1[0m" 200 -
172.31.35.238 - - [23/Apr/2020 22:46:48] "[32mPOST /register HTTP/1.1[0m" 302 -
172.31.35.238 - - [23/Apr/2020 22:46:48] "[37mGET /login HTTP/1.1[0m" 200 -
172.31.35.238 - - [23/Apr/2020 22:46:48] "[37mGET /all_jobs HTTP/1.1[0m" 200 -
172.31.35.238 - - [23/Apr/2020 22:46:52] "[37mGET /register HTTP/1.1[0m" 200 -
172.31.35.238 - - [23/Apr/2020 22:46:52] "[37mGET /all_jobs HTTP/1.1[0m" 200 -
[2020-04-23 22:46:59,531] ERROR in app: Exception on /register [POST]
Traceback (most recent call last):
  File "/home/capstonegroup/.local/lib/python3.6/site-packages/flask/app.py", line 2446, in wsgi_app
    response = self.full_dispatch_request()
  File "/home/capstonegroup/.local/lib/python3.6/site-packages/flask/app.py", line 1951, in full_dispatch_request
    rv = self.handle_user_exception(e)
  File "/home/capstonegroup/.local/lib/python3.6/site-packages/flask/app.py", line 1820, in handle_user_exception
    reraise(exc_type, exc_value, tb)
  File "/home/capstonegroup/.local/lib/python3.6/site-packages/flask/_compat.py", line 39, in reraise
    raise value
  File "/home/capstonegroup/.local/lib/python3.6/site-packages/flask/app.py", line 1949, in full_dispatch_request
    rv = self.dispatch_request()
  File "/home/capstonegroup/.local/lib/python3.6/site-packages/flask/app.py", line 1935, in dispatch_request
    return self.view_functions[rule.endpoint](**req.view_args)
  File "main.py", line 156, in register
    if(user_id > -1):
TypeError: '>' not supported between instances of 'NoneType' and 'int'
172.31.35.238 - - [23/Apr/2020 22:46:59] "[35m[1mPOST /register HTTP/1.1[0m" 500 -
[2020-04-23 22:47:11,049] ERROR in app: Exception on /register [POST]
Traceback (most recent call last):
  File "/home/capstonegroup/.local/lib/python3.6/site-packages/flask/app.py", line 2446, in wsgi_app
    response = self.full_dispatch_request()
  File "/home/capstonegroup/.local/lib/python3.6/site-packages/flask/app.py", line 1951, in full_dispatch_request
    rv = self.handle_user_exception(e)
  File "/home/capstonegroup/.local/lib/python3.6/site-packages/flask/app.py", line 1820, in handle_user_exception
    reraise(exc_type, exc_value, tb)
  File "/home/capstonegroup/.local/lib/python3.6/site-packages/flask/_compat.py", line 39, in reraise
    raise value
  File "/home/capstonegroup/.local/lib/python3.6/site-packages/flask/app.py", line 1949, in full_dispatch_request
    rv = self.dispatch_request()
  File "/home/capstonegroup/.local/lib/python3.6/site-packages/flask/app.py", line 1935, in dispatch_request
    return self.view_functions[rule.endpoint](**req.view_args)
  File "main.py", line 154, in register
    user_id = Register.registerUser(username, password, firstName, lastName, institution)
  File "/var/www/azDNA/azDNA/Register.py", line 26, in registerUser
    cursor.execute(add_user_query, user_data)
  File "/home/capstonegroup/.local/lib/python3.6/site-packages/mysql/connector/cursor.py", line 551, in execute
    self._handle_result(self._connection.cmd_query(stmt))
  File "/home/capstonegroup/.local/lib/python3.6/site-packages/mysql/connector/connection.py", line 490, in cmd_query
    result = self._handle_result(self._send_cmd(ServerCmd.QUERY, query))
  File "/home/capstonegroup/.local/lib/python3.6/site-packages/mysql/connector/connection.py", line 395, in _handle_result
    raise errors.get_exception(packet)
mysql.connector.errors.IntegrityError: 1062 (23000): Duplicate entry 'R@R.edu' for key 'username'
172.31.35.238 - - [23/Apr/2020 22:47:11] "[35m[1mPOST /register HTTP/1.1[0m" 500 -
Traceback (most recent call last):
  File "main.py", line 7, in <module>
    import Register
  File "/var/www/azDNA/azDNA/Register.py", line 6, in <module>
    import Account
  File "/var/www/azDNA/azDNA/Account.py", line 25
    cursor.execute(find_email_by_user_id_query(userId))
                                                      ^
IndentationError: unindent does not match any outer indentation level
172.31.35.238 - - [23/Apr/2020 22:48:59] "[32mGET / HTTP/1.1[0m" 302 -
172.31.35.238 - - [23/Apr/2020 22:48:59] "[37mGET /all_jobs HTTP/1.1[0m" 200 -
172.31.35.238 - - [23/Apr/2020 22:49:00] "[37mGET /all_jobs HTTP/1.1[0m" 200 -
 * Serving Flask app "main" (lazy loading)
 * Environment: production
   WARNING: This is a development server. Do not use it in a production deployment.
   Use a production WSGI server instead.
 * Debug mode: off
 * Running on http://0.0.0.0:9000/ (Press CTRL+C to quit)
172.31.35.238 - - [23/Apr/2020 22:49:44] "[32mGET / HTTP/1.1[0m" 302 -
172.31.35.238 - - [23/Apr/2020 22:49:45] "[37mGET /all_jobs HTTP/1.1[0m" 200 -
172.31.35.238 - - [23/Apr/2020 22:49:45] "[37mGET /all_jobs HTTP/1.1[0m" 200 -
172.31.35.238 - - [23/Apr/2020 22:49:53] "[32mPOST /register HTTP/1.1[0m" 302 -
172.31.35.238 - - [23/Apr/2020 22:49:53] "[37mGET /login HTTP/1.1[0m" 200 -
172.31.35.238 - - [23/Apr/2020 22:49:53] "[37mGET /all_jobs HTTP/1.1[0m" 200 -
172.31.35.238 - - [23/Apr/2020 22:49:55] "[37mGET /register HTTP/1.1[0m" 200 -
172.31.35.238 - - [23/Apr/2020 22:49:55] "[37mGET /all_jobs HTTP/1.1[0m" 200 -
172.31.35.238 - - [23/Apr/2020 22:50:02] "[32mPOST /register HTTP/1.1[0m" 302 -
172.31.35.238 - - [23/Apr/2020 22:50:02] "[37mGET /login HTTP/1.1[0m" 200 -
172.31.35.238 - - [23/Apr/2020 22:50:02] "[37mGET /all_jobs HTTP/1.1[0m" 200 -
